<testsuite errors="0" failures="1" name="Django Project Tests" skips="0" tests="2" time="0.002"><testcase classname="accounting.tests.TestAccountTransaction" name="test_transaction_succed" time="0.000000"><failure message="10 != 11" type="builtins.AssertionError">Traceback (most recent call last):
  File "D:\devantes\tdd_django\accounting\tests.py", line 23, in test_transaction_succed
    self.assertEquals(self.account2.amount, 11)
AssertionError: 10 != 11
</failure></testcase><testcase classname="accounting.tests.TestAccountTransaction" name="test_transaction_whith_enough_money_fails" time="0.000000" /></testsuite>